Workbook

Sheet README
A1: WPH – Room QR Status Register
A2: This workbook is the single data source for the room QR codes. Each QR code opens a web page that reads THIS file, so whatever is saved here is what people see when they scan.
A4: HOW TO UPDATE
A5: 1. Edit the Clearances sheet (per-room data: clearances, remarks) or the Shop Drawings sheet (per-typology data: shop drawing status). Use the drop-down lists.
A6: 2. Save the file (keep the same file name: WPH_Room_Register.xlsx).
A7: 3. Upload it to the GitHub repository (Add file > Upload files, replace the old one). The QR pages update within a few minutes.
A9: HOW VALUES ARE RESOLVED
A10: • Shop Drawings sheet = default per room type (e.g. ID shop drawing status of K01C applies to every K01C room).
A11: • Clearances sheet = per room. If a column with the same header exists in Clearances and is filled, it overrides the Shop Drawings value for that room only.
A12: • Room counts and percentages are calculated automatically by the page from the Clearances sheet. Do not type them.
A14: HOW TO ADD NEW INFORMATION (no code changes)
A15: 1. Add a new column to Clearances (per room) or Shop Drawings (per type) with a clear header, e.g. "Snagging Status".
... A43: FLS sheet – one row per tower/level. Each item has a Material status, then WIR statuses (codes A / B / UR / C / TBS) with dates. Civil (Steel Doors, Wooden Doors, Fire Sealant, Hardware): Material, Rooms WIR, Corridor WIR. MEP (Fire Sealant, Fire Alarm, Fire Fighting): Material, Rooms WIR, Corridor WIR, Elec. Room WIR, BOH WIR. Shown on the level QR page. FLS Rooms sheet – one row per room: a WIR status and date for each item (Steel Doors are level-only). Each room QR page shows the level Material status plus that room's own WIR.

Sheet Clearances
A1: QR ID | B1: Tower | C1: Level | D1: Design Room Tag | E1: Room Type | F1: Room Category | G1: MEP Clearance | H1: MEP Clearance Date | I1: ELV Clearance | J1: ELV Clearance Date | K1: Remarks | L1: ID Source | M1: QR URL
A2: A-L02-BS | B2: Tower A | C2: L02 | D2: AL02G04 | E2: BS | F2: Suite | L2: Type per Room Matrix (drawing shows BS01) | M2: =Config!$B$3&"?room="&A2 -> https://wph-bujv.github.io/wph-rooms/?room=A-L02-BS
A3: A-L02-F03 | B3: Tower A | C3: L02 | D3: AL02G03 | E3: F03 | F3: Family | G3: Provided | H3: 46301 | I3: Provided | J3: 46301 | L3: Typology drawing R01 | M3: =Config!$B$3&"?room="&A3 -> https://wph-bujv.github.io/wph-rooms/?room=A-L02-F03
A4: A-L02-F04 | B4: Tower A | C4: L02 | D4: AL02G11 | E4: F04 | F4: Family | L4: Typology drawing R01 | M4: =Config!$B$3&"?room="&A4 -> https://wph-bujv.github.io/wph-rooms/?room=A-L02-F04
A5: A-L02-FADA | B5: Tower A | C5: L02 | D5: AL02G46 | E5: FADA | F5: Family ADA | L5: Typology drawing R01 | M5: =Config!$B$3&"?room="&A5 -> https://wph-bujv.github.io/wph-rooms/?room=A-L02-FADA
A6: A-L02-K01-01 | B6: Tower A | C6: L02 | D6: AL02G19 | E6: K01 | F6: King | L6: Typology drawing R01 | M6: =Config!$B$3&"?room="&A6 -> https://wph-bujv.github.io/wph-rooms/?room=A-L02-K01-01
A7: A-L02-K01-02 | B7: Tower A | C7: L02 | D7: AL02G23 | E7: K01 | F7: King | L7: Typology drawing R01 | M7: =Config!$B$3&"?room="&A7 -> https://wph-bujv.github.io/wph-rooms/?room=A-L02-K01-02
A8: A-L02-K01-03 | B8: Tower A | C8: L02 | D8: AL02G27 | E8: K01 | F8: King | L8: Typology drawing R01 | M8: =Config!$B$3&"?room="&A8 -> https://wph-bujv.github.io/wph-rooms/?room=A-L02-K01-03
A9: A-L02-K01B-01 | B9: Tower A | C9: L02 | D9: AL02G26 | E9: K01B | F9: King | L9: Typology drawing R01 | M9: =Config!$B$3&"?room="&A9 -> https://wph-bujv.github.io/wph-rooms/?room=A-L02-K01B-01
A10: A-L02-K01B-02 | B10: Tower A | C10: L02 | D10: AL02G30 | E10: K01B | F10: King | L10: Typology drawing R01 | M10: =Config!$B$3&"?room="&A10 -> https://wph-bujv.github.io/wph-rooms/?room=A-L02-K01B-02
A11: A-L02-K01C-01 | B11: Tower A | C11: L02 | D11: AL02G07 | E11: K01C | F11: King | L11: Typology drawing R01 | M11: =Config!$B$3&"?room="&A11 -> https://wph-bujv.github.io/wph-rooms/?room=A-L02-K01C-01
A12: A-L02-K01C-02 | B12: Tower A | C12: L02 | D12: AL02G31 | E12: K01C | F12: King | L12: Typology drawing R01 | M12: =Config!$B$3&"?room="&A12 -> https://wph-bujv.github.io/wph-rooms/?room=A-L02-K01C-02
A13: A-L02-K01C-03 | B13: Tower A | C13: L02 | D13: AL02G35 | E13: K01C | F13: King | L13: Typology drawing R01 | M13: =Config!$B$3&"?room="&A13 -> https://wph-bujv.github.io/wph-rooms/?room=A-L02-K01C-03
A14: A-L02-K01D | B14: Tower A | C14: L02 | D14: AL02G39 | E14: K01D | F14: King | L14: Typology drawing R01 | M14: =Config!$B$3&"?room="&A14 -> https://wph-bujv.github.io/wph-rooms/?room=A-L02-K01D
A15: A-L02-K02-01 | B15: Tower A | C15: L02 | D15: AL02G25 | E15: K02 | F15: King | L15: Typology drawing R01 | M15: =Config!$B$3&"?room="&A15 -> https://wph-bujv.github.io/wph-rooms/?room=A-L02-K02-01
... A554: B-L09-S10 | B554: Tower B | C554: L09 | D554: BL09G87 | E554: S10 | F554: Suite | L554: Typology drawing R01 | M554: =Config!$B$3&"?room="&A554 -> https://wph-bujv.github.io/wph-rooms/?room=B-L09-S10

Sheet Shop Drawings
A1: Room Type | B1: Room Category | C1: ID SD Reference | D1: Coordination Sketch | E1: Coordination Sketch Date | F1: ID SD | I1: Drainage SD | L1: Water Supply SD | O1: Chilled Water SD | R1: Fire Fighting SD | U1: AC SD | X1: Ventilation SD | AA1: CDP SD | AD1: Small Power SD | AG1: Lighting SD | AJ1: ICT System GRMS SD | AM1: ICT GRMS Lighting Control SD
F2: rev. | G2: Workflow | H2: Status | I2: rev. | J2: Workflow | K2: Status | L2: rev. | M2: Workflow | N2: Status | O2: rev. | P2: Workflow | Q2: Status | R2: rev. | S2: Workflow | T2: Status | U2: rev. | V2: Workflow | W2: Status | X2: rev. | Y2: Workflow | Z2: Status | AA2: rev. | AB2: Workflow | AC2: Status | AD2: rev. | AE2: Workflow | AF2: Status | AG2: rev. | AH2: Workflow | AI2: Status | AJ2: rev. | AK2: Workflow | AL2: Status | AM2: rev. | AN2: Workflow | AO2: Status
A3: F01 | B3: Family | C3: WPH-ETC-DRW-SDW-IND-00-ZZZ-42301 | D3: Provided | F3: 0 | H3: B | I3: 0 | J3: WF-054591 | K3: UR | L3: 0 | M3: WF-054503 | N3: UR | O3: 0 | P3: WF-054602 | Q3: UR | R3: 0 | S3: WF-054508 | T3: UR | U3: 0 | V3: WF-053425 | W3: B | X3: 0 | Y3: WF-053212 | Z3: B | AA3: 0 | AB3: WF-054645 | AC3: UR | AD3: 2 | AE3: WF-053780 | AF3: B | AI3: TBS | AJ3: 1 | AK3: WF-048822 | AL3: B | AM3: 1 | AN3: WF-048822 | AO3: B | AQ3: =AND($A3<>"",COUNTIFS($F$2:$AO$2,"Status",$F3:$AO3,"A")+COUNTIFS($F$2:$AO$2,"Status",$F3:$AO3,"B")=COUNTIF($F$2:$AO$2,"Status")) -> FALSE
A4: F02 | B4: Family | C4: WPH-ETC-DRW-SDW-IND-00-ZZZ-42401 | D4: Provided | F4: 0 | H4: B | I4: 0 | J4: WF-053660 | K4: B | L4: 0 | M4: WF-048580 | N4: B | O4: 1 | P4: WF-045331 | Q4: B | R4: 1 | S4: WF-048577 | T4: B | U4: 1 | V4: WF-048036 | W4: B | X4: 1 | Y4: WF-048035 | Z4: B | AA4: 0 | AB4: WF-048696 | AC4: B | AD4: 3 | AE4: WF-046760 | AF4: B | AI4: TBS | AJ4: 2 | AK4: WF-048309 | AL4: B | AM4: 2 | AN4: WF-048309 | AO4: B | AQ4: =AND($A4<>"",COUNTIFS($F$2:$AO$2,"Status",$F4:$AO4,"A")+COUNTIFS($F$2:$AO$2,"Status",$F4:$AO4,"B")=COUNTIF($F$2:$AO$2,"Status")) -> FALSE
A5: F03 | B5: Family | C5: WPH-ETC-DRW-SDW-IND-00-ZZZ-42501 | D5: Provided | F5: 0 | H5: B | I5: 0 | J5: WF-053198 | K5: B | L5: 0 | M5: WF-053210 | N5: B | O5: 1 | P5: WF-053191 | Q5: B | R5: 0 | S5: WF-053204 | T5: C | U5: 0 | V5: WF-053425 | W5: B | X5: 0 | Y5: WF-053212 | Z5: B | AA5: 0 | AB5: WF-053188 | AC5: B | AD5: 2 | AE5: WF-046367 | AF5: B | AG5: 0 | AH5: WF-053161 | AI5: C | AJ5: 1 | AK5: WF-048490 | AL5: B | AM5: 1 | AN5: WF-048490 | AO5: B | AQ5: =AND($A5<>"",COUNTIFS($F$2:$AO$2,"Status",$F5:$AO5,"A")+COUNTIFS($F$2:$AO$2,"Status",$F5:$AO5,"B")=COUNTIF($F$2:$AO$2,"Status")) -> FALSE
A6: F03A | B6: Family | C6: (no drawing number in legend) | D6: Provided | F6: 0 | H6: B | I6: 0 | J6: WF-053529 | K6: B | L6: 0 | M6: WF-053535 | N6: B | O6: 1 | P6: WF-053525 | Q6: B | R6: 0 | S6: WF-053528 | T6: C | U6: 0 | V6: WF-053531 | W6: C | X6: 0 | Y6: WF-053537 | Z6: B | AA6: 0 | AB6: WF-053522 | AC6: B | AD6: 0 | AE6: WF-047609 | AF6: B | AG6: 1 | AH6: WF-053874 | AI6: C | AJ6: 0 | AK6: WF-048805 | AL6: B | AM6: 0 | AN6: WF-048805 | AO6: B | AQ6: =AND($A6<>"",COUNTIFS($F$2:$AO$2,"Status",$F6:$AO6,"A")+COUNTIFS($F$2:$AO$2,"Status",$F6:$AO6,"B")=COUNTIF($F$2:$AO$2,"Status")) -> FALSE
A7: F03B | B7: Family | C7: (no drawing number in legend) | D7: Provided | E7: 46321 | F7: 0 | H7: B | I7: 0 | J7: WF-053529 | K7: B | L7: 0 | M7: WF-053535 | N7: B | O7: 1 | P7: WF-053525 | Q7: B | R7: 0 | S7: WF-053528 | T7: C | U7: 0 | V7: WF-053531 | W7: C | X7: 0 | Y7: WF-053537 | Z7: B | AA7: 0 | AB7: WF-053522 | AC7: B | AD7: 0 | AE7: WF-047609 | AF7: B | AG7: 1 | AH7: WF-053874 | AI7: C | AJ7: 0 | AK7: WF-048805 | AL7: B | AM7: 0 | AN7: WF-048805 | AO7: B | AQ7: =AND($A7<>"",COUNTIFS($F$2:$AO$2,"Status",$F7:$AO7,"A")+COUNTIFS($F$2:$AO$2,"Status",$F7:$AO7,"B")=COUNTIF($F$2:$AO$2,"Status")) -> FALSE
A8: F04 | B8: Family | C8: WPH-ETC-DRW-SDW-IND-00-ZZZ-42801 | D8: Provided | F8: 0 | H8: B | I8: 0 | J8: WF-053147 | K8: B | L8: 1 | M8: WF-052749 | N8: B | O8: 1 | P8: WF-045414 | Q8: B | R8: 0 | S8: WF-052747 | T8: B | U8: 0 | V8: WF-052748 | W8: B | X8: 0 | Y8: WF-052756 | Z8: B | AA8: 1 | AB8: WF-052743 | AC8: B | AD8: 2 | AE8: WF-046286 | AF8: B | AG8: 0 | AH8: WF-051845 | AI8: B | AJ8: 1 | AK8: WF-048485 | AL8: B | AM8: 1 | AN8: WF-048485 | AO8: B | AQ8: =AND($A8<>"",COUNTIFS($F$2:$AO$2,"Status",$F8:$AO8,"A")+COUNTIFS($F$2:$AO$2,"Status",$F8:$AO8,"B")=COUNTIF($F$2:$AO$2,"Status")) -> TRUE
A9: F05 | B9: Family | C9: WPH-ETC-DRW-SDW-IND-00-ZZZ-42901 | D9: Provided | F9: 0 | H9: B | I9: 0 | J9: WF-053552 | K9: B | L9: 0 | M9: WF-053536 | N9: B | O9: 0 | P9: WF-053547 | Q9: TBS | R9: 0 | S9: WF-053556 | T9: C | U9: 0 | V9: WF-053533 | W9: C | X9: 0 | Y9: WF-053538 | Z9: TBS | AA9: 0 | AB9: WF-053544 | AC9: B | AD9: 2 | AE9: WF-048038 | AF9: B | AG9: 0 | AH9: WF-053372 | AI9: B | AJ9: 2 | AK9: WF-048806 | AL9: B | AM9: 2 | AN9: WF-048806 | AO9: B | AQ9: =AND($A9<>"",COUNTIFS($F$2:$AO$2,"Status",$F9:$AO9,"A")+COUNTIFS($F$2:$AO$2,"Status",$F9:$AO9,"B")=COUNTIF($F$2:$AO$2,"Status")) -> FALSE
A10: F06 | B10: Family | C10: WPH-ETC-DRW-SDW-IND-00-ZZZ-43001 | D10: Provided | F10: 0 | H10: B | I10: 0 | J10: WF-052880 | K10: B | L10: 0 | M10: WF-052873 | N10: B | O10: 0 | P10: WF-045416 | Q10: B | R10: 0 | S10: WF-052881 | T10: B | U10: 0 | V10: WF-052871 | W10: B | X10: 0 | Y10: WF-052876 | Z10: B | AA10: 0 | AB10: WF-052772 | AC10: B | AD10: 0 | AE10: WF-048315 | AF10: B | AG10: 0 | AH10: WF-050831 | AI10: B | AJ10: 0 | AK10: WF-048744 | AL10: B | AM10: 0 | AN10: WF-048744 | AO10: B | AQ10: =AND($A10<>"",COUNTIFS($F$2:$AO$2,"Status",$F10:$AO10,"A")+COUNTIFS($F$2:$AO$2,"Status",$F10:$AO10,"B")=COUNTIF($F$2:$AO$2,"Status")) -> TRUE
A11: F07 | B11: Family | C11: WPH-ETC-DRW-SDW-IND-00-ZZZ-43101 | D11: Provided | E11: 46321 | F11: 0 | H11: B | K11: TBS | N11: TBS | Q11: TBS | T11: TBS | W11: TBS | Z11: TBS | AC11: TBS | AD11: 0 | AE11: WF-048250 | AF11: B | AG11: 0 | AH11: WF-051908 | AI11: B | AJ11: 2 | AK11: WF-048736 | AL11: B | AM11: 2 | AN11: WF-048736 | AO11: B | AQ11: =AND($A11<>"",COUNTIFS($F$2:$AO$2,"Status",$F11:$AO11,"A")+COUNTIFS($F$2:$AO$2,"Status",$F11:$AO11,"B")=COUNTIF($F$2:$AO$2,"Status")) -> FALSE
A12: F08 | B12: Family | C12: WPH-ETC-DRW-SDW-IND-00-ZZZ-43201 | D12: Provided | E12: 46321 | F12: 0 | H12: B | K12: TBS | N12: TBS | Q12: TBS | T12: TBS | W12: TBS | Z12: TBS | AC12: TBS | AF12: TBS | AG12: 0 | AH12: WF-050717 | AI12: B | AJ12: 1 | AK12: WF-048742 | AL12: B | AM12: 1 | AN12: WF-048742 | AO12: B | AQ12: =AND($A12<>"",COUNTIFS($F$2:$AO$2,"Status",$F12:$AO12,"A")+COUNTIFS($F$2:$AO$2,"Status",$F12:$AO12,"B")=COUNTIF($F$2:$AO$2,"Status")) -> FALSE
A13: FADA | B13: Family ADA | C13: WPH-ETC-DRW-SDW-IND-00-ZZZ-43301 | D13: Provided | F13: 0 | H13: B | I13: 0 | J13: WF-049298 | K13: B | L13: 0 | M13: WF-049294 | N13: B | O13: 0 | P13: WF-045045 | Q13: B | R13: 0 | S13: WF-048415 | T13: B | U13: 0 | V13: WF-049292 | W13: B | X13: 0 | Y13: WF-049295 | Z13: B | AA13: 0 | AB13: WF-049347 | AC13: B | AD13: 0 | AE13: WF-047595 | AF13: B | AG13: 0 | AH13: WF-051909 | AI13: B | AJ13: 0 | AK13: WF-051923 | AL13: B | AM13: 0 | AN13: WF-051923 | AO13: B | AQ13: =AND($A13<>"",COUNTIFS($F$2:$AO$2,"Status",$F13:$AO13,"A")+COUNTIFS($F$2:$AO$2,"Status",$F13:$AO13,"B")=COUNTIF($F$2:$AO$2,"Status")) -> TRUE
A14: K01 | B14: King | C14: WPH-ETC-DRW-SDW-IND-00-ZZZ-40301 | D14: Not Provided | H14: B | I14: 0 | J14: WF-053783 | K14: B | N14: TBS | Q14: TBS | T14: TBS | W14: TBS | Z14: TBS | AC14: TBS | AF14: TBS | AI14: TBS | AL14: B | AO14: TBS | AQ14: =AND($A14<>"",COUNTIFS($F$2:$AO$2,"Status",$F14:$AO14,"A")+COUNTIFS($F$2:$AO$2,"Status",$F14:$AO14,"B")=COUNTIF($F$2:$AO$2,"Status")) -> FALSE
A15: K01A | B15: King | C15: WPH-ETC-DRW-SDW-IND-00-ZZZ-40301 | D15: Not Provided | H15: B | I15: 0 | J15: WF-054654 | K15: UR | N15: TBS | Q15: TBS | T15: TBS | W15: TBS | Z15: TBS | AC15: TBS | AF15: TBS | AG15: 0 | AH15: WF-051390 | AI15: C | AL15: TBS | AO15: TBS | AQ15: =AND($A15<>"",COUNTIFS($F$2:$AO$2,"Status",$F15:$AO15,"A")+COUNTIFS($F$2:$AO$2,"Status",$F15:$AO15,"B")=COUNTIF($F$2:$AO$2,"Status")) -> FALSE
A16: K01B | B16: King | C16: WPH-ETC-DRW-SDW-IND-00-ZZZ-40301 | D16: Not Provided | H16: B | I16: 0 | J16: WF-054615 | K16: UR | N16: TBS | Q16: TBS | T16: TBS | W16: TBS | Z16: TBS | AC16: TBS | AF16: TBS | AG16: 0 | AH16: WF-051910 | AI16: B | AL16: TBS | AO16: TBS | AQ16: =AND($A16<>"",COUNTIFS($F$2:$AO$2,"Status",$F16:$AO16,"A")+COUNTIFS($F$2:$AO$2,"Status",$F16:$AO16,"B")=COUNTIF($F$2:$AO$2,"Status")) -> FALSE
A17: K01C | B17: King | C17: WPH-ETC-DRW-SDW-IND-00-ZZZ-40301 | D17: Not Provided | H17: B | K17: TBS | N17: TBS | Q17: TBS | T17: TBS | W17: TBS | Z17: TBS | AC17: TBS | AF17: TBS | AG17: 0 | AH17: WF-052891 | AI17: B | AL17: TBS | AO17: TBS | AQ17: =AND($A17<>"",COUNTIFS($F$2:$AO$2,"Status",$F17:$AO17,"A")+COUNTIFS($F$2:$AO$2,"Status",$F17:$AO17,"B")=COUNTIF($F$2:$AO$2,"Status")) -> FALSE
A18: K01C1 | B18: King | C18: WPH-ETC-DRW-SDW-IND-00-ZZZ-40301 | D18: Not Provided | H18: B | K18: TBS | N18: TBS | Q18: TBS | T18: TBS | W18: TBS | Z18: TBS | AC18: TBS | AF18: TBS | AG18: 0 | AH18: WF-053664 | AI18: B | AL18: TBS | AO18: TBS | AQ18: =AND($A18<>"",COUNTIFS($F$2:$AO$2,"Status",$F18:$AO18,"A")+COUNTIFS($F$2:$AO$2,"Status",$F18:$AO18,"B")=COUNTIF($F$2:$AO$2,"Status")) -> FALSE
A19: K01D | B19: King | C19: WPH-ETC-DRW-SDW-IND-00-ZZZ-40301 | D19: Not Provided | H19: B | K19: TBS | N19: TBS | Q19: TBS | T19: TBS | W19: TBS | Z19: TBS | AC19: TBS | AF19: TBS | AG19: 0 | AH19: WF-054248 | AI19: B | AL19: TBS | AO19: TBS | AQ19: =AND($A19<>"",COUNTIFS($F$2:$AO$2,"Status",$F19:$AO19,"A")+COUNTIFS($F$2:$AO$2,"Status",$F19:$AO19,"B")=COUNTIF($F$2:$AO$2,"Status")) -> FALSE
A20: K02 | B20: King | C20: WPH-ETC-DRW-SDW-IND-00-ZZZ-40701 | D20: Not Provided | H20: B | K20: TBS | N20: TBS | Q20: TBS | T20: TBS | W20: TBS | Z20: TBS | AC20: TBS | AF20: TBS | AI20: TBS | AL20: TBS | AO20: TBS | AQ20: =AND($A20<>"",COUNTIFS($F$2:$AO$2,"Status",$F20:$AO20,"A")+COUNTIFS($F$2:$AO$2,"Status",$F20:$AO20,"B")=COUNTIF($F$2:$AO$2,"Status")) -> FALSE
A21: K02A | B21: King | C21: WPH-ETC-DRW-SDW-IND-00-ZZZ-40701 | D21: Not Provided | H21: B | K21: TBS | N21: TBS | Q21: TBS | T21: TBS | W21: TBS | Z21: TBS | AC21: TBS | AF21: TBS | AG21: 0 | AH21: WF-054715 | AI21: UR | AL21: TBS | AO21: TBS | AQ21: =AND($A21<>"",COUNTIFS($F$2:$AO$2,"Status",$F21:$AO21,"A")+COUNTIFS($F$2:$AO$2,"Status",$F21:$AO21,"B")=COUNTIF($F$2:$AO$2,"Status")) -> FALSE
A22: K02B | B22: King | C22: WPH-ETC-DRW-SDW-IND-00-ZZZ-40701 | D22: Not Provided | H22: B | K22: TBS | N22: TBS | Q22: TBS | T22: TBS | W22: TBS | Z22: TBS | AC22: TBS | AF22: TBS | AI22: TBS | AL22: TBS | AO22: TBS | AQ22: =AND($A22<>"",COUNTIFS($F$2:$AO$2,"Status",$F22:$AO22,"A")+COUNTIFS($F$2:$AO$2,"Status",$F22:$AO22,"B")=COUNTIF($F$2:$AO$2,"Status")) -> FALSE
A23: K02C | B23: King | C23: WPH-ETC-DRW-SDW-IND-00-ZZZ-40701 | D23: Not Provided | H23: B | K23: TBS | N23: TBS | Q23: TBS | T23: TBS | W23: TBS | Z23: TBS | AC23: TBS | AF23: TBS | AG23: 0 | AH23: WF-051386 | AI23: B | AL23: TBS | AO23: TBS | AQ23: =AND($A23<>"",COUNTIFS($F$2:$AO$2,"Status",$F23:$AO23,"A")+COUNTIFS($F$2:$AO$2,"Status",$F23:$AO23,"B")=COUNTIF($F$2:$AO$2,"Status")) -> FALSE
A24: K02C1 | B24: King | C24: WPH-ETC-DRW-SDW-IND-00-ZZZ-40701 | D24: Not Provided | H24: B | K24: TBS | N24: TBS | Q24: TBS | T24: TBS | W24: TBS | Z24: TBS | AC24: TBS | AF24: TBS | AG24: 0 | AH24: WF-054716 | AI24: UR | AL24: TBS | AO24: TBS | AQ24: =AND($A24<>"",COUNTIFS($F$2:$AO$2,"Status",$F24:$AO24,"A")+COUNTIFS($F$2:$AO$2,"Status",$F24:$AO24,"B")=COUNTIF($F$2:$AO$2,"Status")) -> FALSE
A25: K02C2 | B25: King | C25: WPH-ETC-DRW-SDW-IND-00-ZZZ-40701 | D25: Not Provided | H25: B | K25: TBS | N25: TBS | Q25: TBS | T25: TBS | W25: TBS | Z25: TBS | AC25: TBS | AF25: TBS | AI25: TBS | AL25: TBS | AO25: TBS | AQ25: =AND($A25<>"",COUNTIFS($F$2:$AO$2,"Status",$F25:$AO25,"A")+COUNTIFS($F$2:$AO$2,"Status",$F25:$AO25,"B")=COUNTIF($F$2:$AO$2,"Status")) -> FALSE
A26: K02D1 | B26: King | C26: WPH-ETC-DRW-SDW-IND-00-ZZZ-40701 | D26: Not Provided | H26: B | K26: TBS | N26: TBS | Q26: TBS | T26: TBS | W26: TBS | Z26: TBS | AC26: TBS | AF26: TBS | AI26: TBS | AL26: TBS | AO26: TBS | AQ26: =AND($A26<>"",COUNTIFS($F$2:$AO$2,"Status",$F26:$AO26,"A")+COUNTIFS($F$2:$AO$2,"Status",$F26:$AO26,"B")=COUNTIF($F$2:$AO$2,"Status")) -> FALSE
A27: K03 | B27: King | C27: WPH-ETC-DRW-SDW-IND-00-ZZZ-41101 | D27: Provided | H27: B | K27: TBS | L27: 0 | N27: B | O27: 0 | Q27: B | T27: TBS | W27: TBS | Z27: TBS | AC27: TBS | AD27: 3 | AF27: B | AG27: 0 | AH27: WF-053373 | AI27: B | AL27: TBS | AO27: TBS | AQ27: =AND($A27<>"",COUNTIFS($F$2:$AO$2,"Status",$F27:$AO27,"A")+COUNTIFS($F$2:$AO$2,"Status",$F27:$AO27,"B")=COUNTIF($F$2:$AO$2,"Status")) -> FALSE
A28: KADA1 | B28: King ADA | C28: WPH-ETC-DRW-SDW-IND-00-ZZZ-41201 | D28: Not Provided | E28: 46321 | F28: 0 | H28: B | K28: TBS | L28: 0 | N28: B | O28: 1 | Q28: B | T28: TBS | W28: TBS | Z28: TBS | AC28: TBS | AD28: 2 | AF28: B | AG28: 0 | AH28: WF-051388 | AI28: B | AL28: TBS | AO28: TBS | AQ28: =AND($A28<>"",COUNTIFS($F$2:$AO$2,"Status",$F28:$AO28,"A")+COUNTIFS($F$2:$AO$2,"Status",$F28:$AO28,"B")=COUNTIF($F$2:$AO$2,"Status")) -> FALSE
A29: KADA2 | B29: King ADA | C29: (no drawing number in legend) | D29: Not Provided | E29: 46321 | F29: 0 | H29: B | K29: TBS | N29: TBS | Q29: TBS | T29: TBS | W29: TBS | Z29: TBS | AC29: TBS | AD29: 0 | AF29: B | AG29: 0 | AH29: WF-054352 | AI29: B | AL29: TBS | AO29: TBS | AQ29: =AND($A29<>"",COUNTIFS($F$2:$AO$2,"Status",$F29:$AO29,"A")+COUNTIFS($F$2:$AO$2,"Status",$F29:$AO29,"B")=COUNTIF($F$2:$AO$2,"Status")) -> FALSE
A30: Q01 | B30: Queen | C30: WPH-ETC-DRW-SDW-IND-00-ZZZ-41401 | D30: Not Provided | H30: B | I30: 0 | J30: WF-051454 | K30: B | L30: 0 | M30: WF-051460 | N30: B | O30: 0 | P30: WF-051455 | Q30: C | R30: 0 | S30: WF-051457 | T30: B | U30: 0 | V30: WF-051458 | W30: B | X30: 0 | Y30: WF-051499 | Z30: B | AA30: 0 | AB30: WF-051456 | AC30: B | AD30: 1 | AE30: WF-051384 | AF30: B | AG30: 0 | AH30: WF-051388 | AI30: B | AJ30: 0 | AK30: WF-053082 | AL30: B | AM30: 0 | AN30: WF-053082 | AO30: B | AQ30: =AND($A30<>"",COUNTIFS($F$2:$AO$2,"Status",$F30:$AO30,"A")+COUNTIFS($F$2:$AO$2,"Status",$F30:$AO30,"B")=COUNTIF($F$2:$AO$2,"Status")) -> FALSE
A31: Q01C | B31: Queen | C31: WPH-ETC-DRW-SDW-IND-00-ZZZ-41401 | D31: Not Provided | H31: B | I31: 1 | J31: WF-022464 | K31: B | L31: 0 | M31: WF-027277 | N31: B | O31: 0 | P31: WF-027232 | Q31: C | R31: 0 | S31: WF-027146 | T31: B | U31: 0 | V31: WF-025402 | W31: B | X31: 2 | Y31: WF-036591 | Z31: B | AA31: 0 | AB31: WF-026851 | AC31: B | AD31: 3 | AE31: WF-054259 | AF31: B | AG31: 0 | AH31: WF-054352 | AI31: B | AJ31: 0 | AK31: WF-053085 | AL31: B | AM31: 0 | AN31: WF-053085 | AO31: B | AQ31: =AND($A31<>"",COUNTIFS($F$2:$AO$2,"Status",$F31:$AO31,"A")+COUNTIFS($F$2:$AO$2,"Status",$F31:$AO31,"B")=COUNTIF($F$2:$AO$2,"Status")) -> FALSE
A32: Q01C1 | B32: Queen | C32: WPH-ETC-DRW-SDW-IND-00-ZZZ-41401 | D32: Not Provided | H32: B | I32: 1 | J32: WF-022464 | K32: B | L32: 0 | M32: WF-027277 | N32: B | O32: 0 | P32: WF-027232 | Q32: C | R32: 0 | S32: WF-027146 | T32: B | U32: 0 | V32: WF-025402 | W32: B | X32: 2 | Y32: WF-036591 | Z32: B | AA32: 0 | AB32: WF-026851 | AC32: B | AD32: 2 | AE32: WF-054594 | AF32: UR | AG32: 0 | AH32: WF-054592 | AI32: UR | AJ32: 0 | AK32: WF-053096 | AL32: B | AM32: 0 | AN32: WF-053096 | AO32: B | AQ32: =AND($A32<>"",COUNTIFS($F$2:$AO$2,"Status",$F32:$AO32,"A")+COUNTIFS($F$2:$AO$2,"Status",$F32:$AO32,"B")=COUNTIF($F$2:$AO$2,"Status")) -> FALSE
A33: Q02A | B33: Queen | C33: WPH-ETC-DRW-SDW-IND-00-ZZZ-41601 | D33: Not Provided | H33: B | I33: 0 | J33: WF-051454 | K33: B | L33: 0 | M33: WF-051460 | N33: B | O33: 0 | P33: WF-051455 | Q33: C | R33: 0 | S33: WF-051457 | T33: B | U33: 0 | V33: WF-051458 | W33: B | X33: 0 | Y33: WF-051499 | Z33: B | AA33: 0 | AB33: WF-051456 | AC33: B | AD33: 0 | AE33: WF-054713 | AF33: UR | AG33: 0 | AH33: WF-054712 | AI33: UR | AJ33: 0 | AK33: WF-053271 | AL33: B | AM33: 0 | AN33: WF-053271 | AO33: B | AQ33: =AND($A33<>"",COUNTIFS($F$2:$AO$2,"Status",$F33:$AO33,"A")+COUNTIFS($F$2:$AO$2,"Status",$F33:$AO33,"B")=COUNTIF($F$2:$AO$2,"Status")) -> FALSE
A34: Q02C | B34: Queen | C34: WPH-ETC-DRW-SDW-IND-00-ZZZ-41601 | D34: Not Provided | H34: B | I34: 0 | J34: WF-053005 | K34: B | L34: 0 | M34: WF-053151 | N34: B | O34: 2 | P34: WF-053157 | Q34: B | R34: 0 | S34: WF-053223 | T34: B | U34: 0 | V34: WF-053004 | W34: B | X34: 0 | Y34: WF-053006 | Z34: B | AA34: 0 | AB34: WF-053003 | AC34: B | AD34: 0 | AE34: WF-046759 | AF34: B | AG34: 0 | AH34: WF-052890 | AI34: B | AJ34: 0 | AK34: WF-052087 | AL34: B | AM34: 0 | AN34: WF-052087 | AO34: B | AQ34: =AND($A34<>"",COUNTIFS($F$2:$AO$2,"Status",$F34:$AO34,"A")+COUNTIFS($F$2:$AO$2,"Status",$F34:$AO34,"B")=COUNTIF($F$2:$AO$2,"Status")) -> TRUE
A35: Q02C1 | B35: Queen | C35: WPH-ETC-DRW-SDW-IND-00-ZZZ-41601 | D35: Not Provided | H35: B | K35: TBS | N35: TBS | Q35: TBS | T35: TBS | W35: TBS | Z35: TBS | AC35: TBS | AD35: 0 | AE35: WF-046759 | AF35: B | AG35: 0 | AH35: WF-052890 | AI35: B | AJ35: 0 | AK35: WF-052087 | AL35: B | AM35: 0 | AN35: WF-052087 | AO35: B | AQ35: =AND($A35<>"",COUNTIFS($F$2:$AO$2,"Status",$F35:$AO35,"A")+COUNTIFS($F$2:$AO$2,"Status",$F35:$AO35,"B")=COUNTIF($F$2:$AO$2,"Status")) -> FALSE
A36: Q02C2 | B36: Queen | C36: WPH-ETC-DRW-SDW-IND-00-ZZZ-41601 | D36: Not Provided | H36: B | K36: TBS | N36: TBS | Q36: TBS | T36: TBS | W36: TBS | Z36: TBS | AC36: TBS | AF36: TBS | AI36: TBS | AL36: TBS | AO36: TBS | AQ36: =AND($A36<>"",COUNTIFS($F$2:$AO$2,"Status",$F36:$AO36,"A")+COUNTIFS($F$2:$AO$2,"Status",$F36:$AO36,"B")=COUNTIF($F$2:$AO$2,"Status")) -> FALSE
A37: Q02D | B37: Queen | C37: WPH-ETC-DRW-SDW-IND-00-ZZZ-41601 | D37: Not Provided | H37: B | K37: TBS | N37: TBS | Q37: TBS | T37: TBS | W37: TBS | Z37: TBS | AC37: TBS | AF37: TBS | AI37: TBS | AL37: TBS | AO37: TBS | AQ37: =AND($A37<>"",COUNTIFS($F$2:$AO$2,"Status",$F37:$AO37,"A")+COUNTIFS($F$2:$AO$2,"Status",$F37:$AO37,"B")=COUNTIF($F$2:$AO$2,"Status")) -> FALSE
A38: Q02E | B38: Queen | C38: WPH-ETC-DRW-SDW-IND-00-ZZZ-41601 | D38: Not Provided | H38: B | K38: TBS | N38: TBS | Q38: TBS | T38: TBS | W38: TBS | Z38: TBS | AC38: TBS | AF38: TBS | AI38: TBS | AL38: TBS | AO38: TBS | AQ38: =AND($A38<>"",COUNTIFS($F$2:$AO$2,"Status",$F38:$AO38,"A")+COUNTIFS($F$2:$AO$2,"Status",$F38:$AO38,"B")=COUNTIF($F$2:$AO$2,"Status")) -> FALSE
A39: Q03 | B39: Queen | C39: WPH-ETC-DRW-SDW-IND-00-ZZZ-42001 | D39: Not Provided | H39: B | I39: 0 | K39: B | L39: 0 | N39: B | O39: 0 | Q39: C | R39: 0 | T39: B | U39: 0 | W39: B | X39: 0 | Z39: B | AA39: 0 | AC39: B | AD39: 1 | AF39: B | AG39: 0 | AI39: B | AL39: UR | AO39: UR | AQ39: =AND($A39<>"",COUNTIFS($F$2:$AO$2,"Status",$F39:$AO39,"A")+COUNTIFS($F$2:$AO$2,"Status",$F39:$AO39,"B")=COUNTIF($F$2:$AO$2,"Status")) -> FALSE
A40: Q04 | B40: Queen | C40: WPH-ETC-DRW-SDW-IND-00-ZZZ-42101 | D40: Not Provided | H40: B | I40: 1 | K40: B | L40: 0 | N40: B | O40: 0 | Q40: C | R40: 0 | T40: B | U40: 0 | W40: B | X40: 2 | Z40: B | AA40: 0 | AC40: B | AD40: 2 | AF40: C | AI40: TBS | AL40: TBS | AO40: TBS | AQ40: =AND($A40<>"",COUNTIFS($F$2:$AO$2,"Status",$F40:$AO40,"A")+COUNTIFS($F$2:$AO$2,"Status",$F40:$AO40,"B")=COUNTIF($F$2:$AO$2,"Status")) -> FALSE
...

Sheet FLS
A1: Tower | B1: Level | C1: Level Code | D1: Civil - Steel Doors - Material | E1: Civil - Steel Doors - Material Date | F1: Civil - Steel Doors - Rooms WIR | G1: Civil - Steel Doors - Rooms WIR Date | H1: Civil - Steel Doors - Corridor WIR | I1: Civil - Steel Doors - Corridor WIR Date | J1: Civil - Wooden Doors - Material | K1: Civil - Wooden Doors - Material Date | L1: Civil - Wooden Doors - Rooms WIR | M1: Civil - Wooden Doors - Rooms WIR Date | N1: Civil - Wooden Doors - Corridor WIR | O1: Civil - Wooden Doors - Corridor WIR Date | P1: Civil - Fire Sealant - Material | Q1: Civil - Fire Sealant - Material Date | R1: Civil - Fire Sealant - Rooms WIR | S1: Civil - Fire Sealant - Rooms WIR Date | T1: Civil - Fire Sealant - Corridor WIR | U1: Civil - Fire Sealant - Corridor WIR Date | V1: Civil - Hardware - Material | W1: Civil - Hardware - Material Date | X1: Civil - Hardware - Rooms WIR | Y1: Civil - Hardware - Rooms WIR Date | Z1: Civil - Hardware - Corridor WIR | AA1: Civil - Hardware - Corridor WIR Date | AB1: MEP - Fire Sealant - Material | AC1: MEP - Fire Sealant - Material Date | AD1: MEP - Fire Sealant - Rooms WIR | AE1: MEP - Fire Sealant - Rooms WIR Date | AF1: MEP - Fire Sealant - Corridor WIR | AG1: MEP - Fire Sealant - Corridor WIR Date | AH1: MEP - Fire Sealant - Elec. Room WIR | AI1: MEP - Fire Sealant - Elec. Room WIR Date | AJ1: MEP - Fire Sealant - BOH WIR | AK1: MEP - Fire Sealant - BOH WIR Date | AL1: MEP - Fire Alarm - Material | AM1: MEP - Fire Alarm - Material Date | AN1: MEP - Fire Alarm - Rooms WIR | AO1: MEP - Fire Alarm - Rooms WIR Date | AP1: MEP - Fire Alarm - Corridor WIR | AQ1: MEP - Fire Alarm - Corridor WIR Date | AR1: MEP - Fire Alarm - Elec. Room WIR | AS1: MEP - Fire Alarm - Elec. Room WIR Date | AT1: MEP - Fire Alarm - BOH WIR | AU1: MEP - Fire Alarm - BOH WIR Date | AV1: MEP - Fire Fighting - Material | AW1: MEP - Fire Fighting - Material Date | AX1: MEP - Fire Fighting - Rooms WIR | AY1: MEP - Fire Fighting - Rooms WIR Date | AZ1: MEP - Fire Fighting - Corridor WIR | BA1: MEP - Fire Fighting - Corridor WIR Date | BB1: MEP - Fire Fighting - Elec. Room WIR | BC1: MEP - Fire Fighting - Elec. Room WIR Date | BD1: MEP - Fire Fighting - BOH WIR | BE1: MEP - Fire Fighting - BOH WIR Date
A2: Tower A | B2: L02 | C2: AL02 | D2: B | F2: TBS | H2: TBS | J2: TBS | L2: TBS | N2: TBS | P2: B | R2: TBS | T2: TBS | V2: TBS | X2: TBS | Z2: TBS | AB2: TBS | AD2: TBS | AF2: TBS | AH2: TBS | AJ2: TBS | AL2: TBS | AN2: TBS | AP2: TBS | AR2: TBS | AT2: TBS | AV2: TBS | AX2: TBS | AZ2: TBS | BB2: TBS | BD2: TBS
A3: Tower A | B3: L03 | C3: AL03 | D3: B | F3: TBS | H3: TBS | J3: TBS | L3: TBS | N3: TBS | P3: B | R3: TBS | T3: TBS | V3: TBS | X3: TBS | Z3: TBS | AB3: TBS | AD3: TBS | AF3: TBS | AH3: TBS | AJ3: TBS | AL3: TBS | AN3: TBS | AP3: TBS | AR3: TBS | AT3: TBS | AV3: TBS | AX3: TBS | AZ3: TBS | BB3: TBS | BD3: TBS
A4: Tower A | B4: L04 | C4: AL04 | D4: B | F4: TBS | H4: TBS | J4: TBS | L4: TBS | N4: TBS | P4: B | R4: TBS | T4: TBS | V4: TBS | X4: TBS | Z4: TBS | AB4: TBS | AD4: TBS | AF4: TBS | AH4: TBS | AJ4: TBS | AL4: TBS | AN4: TBS | AP4: TBS | AR4: TBS | AT4: TBS | AV4: TBS | AX4: TBS | AZ4: TBS | BB4: TBS | BD4: TBS
A5: Tower A | B5: L05 | C5: AL05 | D5: B | F5: TBS | H5: TBS | J5: TBS | L5: TBS | N5: TBS | P5: B | R5: TBS | T5: TBS | V5: TBS | X5: TBS | Z5: TBS | AB5: TBS | AD5: TBS | AF5: TBS | AH5: TBS | AJ5: TBS | AL5: TBS | AN5: TBS | AP5: TBS | AR5: TBS | AT5: TBS | AV5: TBS | AX5: TBS | AZ5: TBS | BB5: TBS | BD5: TBS
A6: Tower A | B6: L06 | C6: AL06 | D6: B | F6: TBS | H6: TBS | J6: TBS | L6: TBS | N6: TBS | P6: B | R6: TBS | T6: TBS | V6: TBS | X6: TBS | Z6: TBS | AB6: TBS | AD6: TBS | AF6: TBS | AH6: TBS | AJ6: TBS | AL6: TBS | AN6: TBS | AP6: TBS | AR6: TBS | AT6: TBS | AV6: TBS | AX6: TBS | AZ6: TBS | BB6: TBS | BD6: TBS
A7: Tower A | B7: L07 | C7: AL07 | D7: B | F7: TBS | H7: TBS | J7: TBS | L7: TBS | N7: TBS | P7: B | R7: TBS | T7: TBS | V7: TBS | X7: TBS | Z7: TBS | AB7: TBS | AD7: TBS | AF7: TBS | AH7: TBS | AJ7: TBS | AL7: TBS | AN7: TBS | AP7: TBS | AR7: TBS | AT7: TBS | AV7: TBS | AX7: TBS | AZ7: TBS | BB7: TBS | BD7: TBS
A8: Tower A | B8: L08 | C8: AL08 | D8: B | F8: TBS | H8: TBS | J8: TBS | L8: TBS | N8: TBS | P8: B | R8: TBS | T8: TBS | V8: TBS | X8: TBS | Z8: TBS | AB8: TBS | AD8: TBS | AF8: TBS | AH8: TBS | AJ8: TBS | AL8: TBS | AN8: TBS | AP8: TBS | AR8: TBS | AT8: TBS | AV8: TBS | AX8: TBS | AZ8: TBS | BB8: TBS | BD8: TBS
A9: Tower A | B9: L09 | C9: AL09 | D9: B | F9: TBS | H9: TBS | J9: TBS | L9: TBS | N9: TBS | P9: B | R9: TBS | T9: TBS | V9: TBS | X9: TBS | Z9: TBS | AB9: TBS | AD9: TBS | AF9: TBS | AH9: TBS | AJ9: TBS | AL9: TBS | AN9: TBS | AP9: TBS | AR9: TBS | AT9: TBS | AV9: TBS | AX9: TBS | AZ9: TBS | BB9: TBS | BD9: TBS
A10: Tower B | B10: L01 | C10: BL01 | D10: B | F10: TBS | H10: TBS | J10: TBS | L10: TBS | N10: TBS | P10: B | R10: TBS | T10: TBS | V10: TBS | X10: TBS | Z10: TBS | AB10: TBS | AD10: TBS | AF10: TBS | AH10: TBS | AJ10: TBS | AL10: TBS | AN10: TBS | AP10: TBS | AR10: TBS | AT10: TBS | AV10: TBS | AX10: TBS | AZ10: TBS | BB10: TBS | BD10: TBS
A11: Tower B | B11: L02 | C11: BL02 | D11: B | F11: TBS | H11: TBS | J11: TBS | L11: TBS | N11: TBS | P11: B | R11: TBS | T11: TBS | V11: TBS | X11: TBS | Z11: TBS | AB11: TBS | AD11: TBS | AF11: TBS | AH11: TBS | AJ11: TBS | AL11: TBS | AN11: TBS | AP11: TBS | AR11: TBS | AT11: TBS | AV11: TBS | AX11: TBS | AZ11: TBS | BB11: TBS | BD11: TBS
A12: Tower B | B12: L03 | C12: BL03 | D12: B | F12: TBS | H12: TBS | J12: TBS | L12: TBS | N12: TBS | P12: B | R12: TBS | T12: TBS | V12: TBS | X12: TBS | Z12: TBS | AB12: TBS | AD12: TBS | AF12: TBS | AH12: TBS | AJ12: TBS | AL12: TBS | AN12: TBS | AP12: TBS | AR12: TBS | AT12: TBS | AV12: TBS | AX12: TBS | AZ12: TBS | BB12: TBS | BD12: TBS
A13: Tower B | B13: L04 | C13: BL04 | D13: B | F13: TBS | H13: TBS | J13: TBS | L13: TBS | N13: TBS | P13: B | R13: TBS | T13: TBS | V13: TBS | X13: TBS | Z13: TBS | AB13: TBS | AD13: TBS | AF13: TBS | AH13: TBS | AJ13: TBS | AL13: TBS | AN13: TBS | AP13: TBS | AR13: TBS | AT13: TBS | AV13: TBS | AX13: TBS | AZ13: TBS | BB13: TBS | BD13: TBS
... A18: Tower B | B18: L09 | C18: BL09 | D18: B | F18: TBS | H18: TBS | J18: TBS | L18: TBS | N18: TBS | P18: B | R18: TBS | T18: TBS | V18: TBS | X18: TBS | Z18: TBS | AB18: TBS | AD18: TBS | AF18: TBS | AH18: TBS | AJ18: TBS | AL18: TBS | AN18: TBS | AP18: TBS | AR18: TBS | AT18: TBS | AV18: TBS | AX18: TBS | AZ18: TBS | BB18: TBS | BD18: TBS

Sheet FLS Rooms
A1: QR ID | B1: Tower | C1: Level | D1: Design Room Tag | E1: Room Type | F1: Civil - Wooden Doors - WIR | G1: Civil - Wooden Doors - WIR Date | H1: Civil - Fire Sealant - WIR | I1: Civil - Fire Sealant - WIR Date | J1: Civil - Hardware - WIR | K1: Civil - Hardware - WIR Date | L1: MEP - Fire Sealant - WIR | M1: MEP - Fire Sealant - WIR Date | N1: MEP - Fire Alarm - WIR | O1: MEP - Fire Alarm - WIR Date | P1: MEP - Fire Fighting - WIR | Q1: MEP - Fire Fighting - WIR Date
A2: A-L02-BS | B2: Tower A | C2: L02 | D2: AL02G04 | E2: BS | F2: TBS | H2: TBS | J2: TBS | L2: TBS | N2: TBS | P2: TBS
A3: A-L02-F03 | B3: Tower A | C3: L02 | D3: AL02G03 | E3: F03 | F3: TBS | H3: TBS | J3: TBS | L3: TBS | N3: TBS | P3: TBS
A4: A-L02-F04 | B4: Tower A | C4: L02 | D4: AL02G11 | E4: F04 | F4: TBS | H4: TBS | J4: TBS | L4: TBS | N4: TBS | P4: TBS
A5: A-L02-FADA | B5: Tower A | C5: L02 | D5: AL02G46 | E5: FADA | F5: TBS | H5: TBS | J5: TBS | L5: TBS | N5: TBS | P5: TBS
A6: A-L02-K01-01 | B6: Tower A | C6: L02 | D6: AL02G19 | E6: K01 | F6: TBS | H6: TBS | J6: TBS | L6: TBS | N6: TBS | P6: TBS
A7: A-L02-K01-02 | B7: Tower A | C7: L02 | D7: AL02G23 | E7: K01 | F7: TBS | H7: TBS | J7: TBS | L7: TBS | N7: TBS | P7: TBS
A8: A-L02-K01-03 | B8: Tower A | C8: L02 | D8: AL02G27 | E8: K01 | F8: TBS | H8: TBS | J8: TBS | L8: TBS | N8: TBS | P8: TBS
A9: A-L02-K01B-01 | B9: Tower A | C9: L02 | D9: AL02G26 | E9: K01B | F9: TBS | H9: TBS | J9: TBS | L9: TBS | N9: TBS | P9: TBS
A10: A-L02-K01B-02 | B10: Tower A | C10: L02 | D10: AL02G30 | E10: K01B | F10: TBS | H10: TBS | J10: TBS | L10: TBS | N10: TBS | P10: TBS
A11: A-L02-K01C-01 | B11: Tower A | C11: L02 | D11: AL02G07 | E11: K01C | F11: TBS | H11: TBS | J11: TBS | L11: TBS | N11: TBS | P11: TBS
A12: A-L02-K01C-02 | B12: Tower A | C12: L02 | D12: AL02G31 | E12: K01C | F12: TBS | H12: TBS | J12: TBS | L12: TBS | N12: TBS | P12: TBS
A13: A-L02-K01C-03 | B13: Tower A | C13: L02 | D13: AL02G35 | E13: K01C | F13: TBS | H13: TBS | J13: TBS | L13: TBS | N13: TBS | P13: TBS
... A554: B-L09-S10 | B554: Tower B | C554: L09 | D554: BL09G87 | E554: S10 | F554: TBS | H554: TBS | J554: TBS | L554: TBS | N554: TBS | P554: TBS

Sheet Fields
A1: Column | B1: Label | C1: Section | D1: Order | E1: Show | F1: Format
A2: Room Category | B2: Category | C2: Room | D2: 1 | E2: Y | F2: text
A3: _TypeCountTower | B3: Rooms of this type in tower | C3: Room type quantity | D3: 10 | E3: Y | F3: text
A4: _TypePctTower | B4: Share of tower rooms | C4: Room type quantity | D4: 11 | E4: Y | F4: text
A5: _TypeCountAll | B5: Rooms of this type – Towers A & B | C5: Room type quantity | D5: 12 | E5: Y | F5: text
A6: _TypePctAll | B6: Share of all rooms (A & B) | C6: Room type quantity | D6: 13 | E6: Y | F6: text
A7: MEP Clearance | B7: MEP clearance | C7: 4. Clearances | D7: 60 | E7: Y | F7: status
A8: MEP Clearance Date | B8: MEP clearance date | C8: 4. Clearances | D8: 61 | E8: Y | F8: date
A9: ELV Clearance | B9: ELV clearance | C9: 4. Clearances | D9: 62 | E9: Y | F9: status
A10: ELV Clearance Date | B10: ELV clearance date | C10: 4. Clearances | D10: 63 | E10: Y | F10: date
A11: Remarks | B11: Remarks | C11: Notes | D11: 90 | E11: Y | F11: text
A12: QR URL | D12: 99 | E12: N | F12: text
A13: ID Source | D13: 99 | E13: N | F13: text
A14: QR ID | D14: 99 | E14: N | F14: text
A15: Tower | D15: 99 | E15: N | F15: text
A16: Level | D16: 99 | E16: N | F16: text
A17: Design Room Tag | B17: Design room tag | C17: Room | D17: 2 | E17: Y | F17: text
A18: Room Type | D18: 99 | E18: N | F18: text
A19: Coordination Sketch | B19: Sketch | C19: Shop drawings | D19: 20 | E19: Y | F19: sketch
A20: ID SD Status | B20: ID | C20: Shop drawings | D20: 21 | E20: Y | F20: sd
A21: MEP SD - Drainage Network | B21: Drainage Network | C21: Shop drawings | D21: 22 | E21: Y | F21: sd
A22: MEP SD - Water Supply Network | B22: Water Supply Network | C22: Shop drawings | D22: 23 | E22: Y | F22: sd
A23: MEP SD - Chilled Water Network | B23: Chilled Water Network | C23: Shop drawings | D23: 24 | E23: Y | F23: sd
A24: MEP SD - Fire Fighting Network | B24: Fire Fighting Network | C24: Shop drawings | D24: 25 | E24: Y | F24: sd
A25: MEP SD - AC System | B25: AC System | C25: Shop drawings | D25: 26 | E25: Y | F25: sd
A26: MEP SD - Ventilation System | B26: Ventilation System | C26: Shop drawings | D26: 27 | E26: Y | F26: sd
A27: MEP SD - CDP System | B27: CDP System | C27: Shop drawings | D27: 28 | E27: Y | F27: sd
A28: MEP SD - Small Power | B28: Small Power | C28: Shop drawings | D28: 29 | E28: Y | F28: sd
A29: MEP SD - Lighting | B29: Lighting | C29: Shop drawings | D29: 30 | E29: Y | F29: sd
A30: ELV SD - ICT System GRMS | B30: ICT System GRMS | C30: Shop drawings | D30: 31 | E30: Y | F30: sd
A31: ELV SD - ICT GRMS Lighting Control | B31: ICT GRMS Lighting Control | C31: Shop drawings | D31: 32 | E31: Y | F31: sd
A32: ID SD Reference | D32: 99 | E32: N | F32: text
A33: ID SD Revision | D33: 99 | E33: N | F33: text
A35: Coordination Sketch Date | D35: 99 | E35: N | F35: text
A36: MEP SD - Drainage Network Rev | D36: 99 | E36: N | F36: text
A37: MEP SD - Water Supply Network Rev | D37: 99 | E37: N | F37: text
A38: MEP SD - Chilled Water Network Rev | D38: 99 | E38: N | F38: text
A39: MEP SD - Fire Fighting Network Rev | D39: 99 | E39: N | F39: text
A40: MEP SD - AC System Rev | D40: 99 | E40: N | F40: text
A41: MEP SD - Ventilation System Rev | D41: 99 | E41: N | F41: text
...

Sheet Summary
A1: Room Type | B1: Category | C1: Tower A | D1: % of Tower A | E1: Tower B | F1: % of Tower B | G1: A & B | H1: % of A & B
A2: F01 | B2: Family | C2: =COUNTIFS(Clearances!$E:$E,$A2,Clearances!$B:$B,"Tower A") -> 0 | D2: =C2/COUNTIF(Clearances!$B:$B,"Tower A") -> 0 | E2: =COUNTIFS(Clearances!$E:$E,$A2,Clearances!$B:$B,"Tower B") -> 1 | F2: =E2/COUNTIF(Clearances!$B:$B,"Tower B") -> 0.003649635 | G2: =C2+E2 -> 1 | H2: =G2/(COUNTA(Clearances!$A:$A)-1) -> 0.0018083183
A3: F02 | B3: Family | C3: =COUNTIFS(Clearances!$E:$E,$A3,Clearances!$B:$B,"Tower A") -> 0 | D3: =C3/COUNTIF(Clearances!$B:$B,"Tower A") -> 0 | E3: =COUNTIFS(Clearances!$E:$E,$A3,Clearances!$B:$B,"Tower B") -> 9 | F3: =E3/COUNTIF(Clearances!$B:$B,"Tower B") -> 0.032846715 | G3: =C3+E3 -> 9 | H3: =G3/(COUNTA(Clearances!$A:$A)-1) -> 0.016274864
A4: F03 | B4: Family | C4: =COUNTIFS(Clearances!$E:$E,$A4,Clearances!$B:$B,"Tower A") -> 5 | D4: =C4/COUNTIF(Clearances!$B:$B,"Tower A") -> 0.017921147 | E4: =COUNTIFS(Clearances!$E:$E,$A4,Clearances!$B:$B,"Tower B") -> 0 | F4: =E4/COUNTIF(Clearances!$B:$B,"Tower B") -> 0 | G4: =C4+E4 -> 5 | H4: =G4/(COUNTA(Clearances!$A:$A)-1) -> 0.0090415913
A5: F03A | B5: Family | C5: =COUNTIFS(Clearances!$E:$E,$A5,Clearances!$B:$B,"Tower A") -> 2 | D5: =C5/COUNTIF(Clearances!$B:$B,"Tower A") -> 0.0071684588 | E5: =COUNTIFS(Clearances!$E:$E,$A5,Clearances!$B:$B,"Tower B") -> 0 | F5: =E5/COUNTIF(Clearances!$B:$B,"Tower B") -> 0 | G5: =C5+E5 -> 2 | H5: =G5/(COUNTA(Clearances!$A:$A)-1) -> 0.0036166365
A6: F03B | B6: Family | C6: =COUNTIFS(Clearances!$E:$E,$A6,Clearances!$B:$B,"Tower A") -> 2 | D6: =C6/COUNTIF(Clearances!$B:$B,"Tower A") -> 0.0071684588 | E6: =COUNTIFS(Clearances!$E:$E,$A6,Clearances!$B:$B,"Tower B") -> 0 | F6: =E6/COUNTIF(Clearances!$B:$B,"Tower B") -> 0 | G6: =C6+E6 -> 2 | H6: =G6/(COUNTA(Clearances!$A:$A)-1) -> 0.0036166365
A7: F04 | B7: Family | C7: =COUNTIFS(Clearances!$E:$E,$A7,Clearances!$B:$B,"Tower A") -> 8 | D7: =C7/COUNTIF(Clearances!$B:$B,"Tower A") -> 0.028673835 | E7: =COUNTIFS(Clearances!$E:$E,$A7,Clearances!$B:$B,"Tower B") -> 0 | F7: =E7/COUNTIF(Clearances!$B:$B,"Tower B") -> 0 | G7: =C7+E7 -> 8 | H7: =G7/(COUNTA(Clearances!$A:$A)-1) -> 0.014466546
A8: F05 | B8: Family | C8: =COUNTIFS(Clearances!$E:$E,$A8,Clearances!$B:$B,"Tower A") -> 7 | D8: =C8/COUNTIF(Clearances!$B:$B,"Tower A") -> 0.025089606 | E8: =COUNTIFS(Clearances!$E:$E,$A8,Clearances!$B:$B,"Tower B") -> 0 | F8: =E8/COUNTIF(Clearances!$B:$B,"Tower B") -> 0 | G8: =C8+E8 -> 7 | H8: =G8/(COUNTA(Clearances!$A:$A)-1) -> 0.012658228
A9: F06 | B9: Family | C9: =COUNTIFS(Clearances!$E:$E,$A9,Clearances!$B:$B,"Tower A") -> 0 | D9: =C9/COUNTIF(Clearances!$B:$B,"Tower A") -> 0 | E9: =COUNTIFS(Clearances!$E:$E,$A9,Clearances!$B:$B,"Tower B") -> 8 | F9: =E9/COUNTIF(Clearances!$B:$B,"Tower B") -> 0.02919708 | G9: =C9+E9 -> 8 | H9: =G9/(COUNTA(Clearances!$A:$A)-1) -> 0.014466546
A10: F07 | B10: Family | C10: =COUNTIFS(Clearances!$E:$E,$A10,Clearances!$B:$B,"Tower A") -> 0 | D10: =C10/COUNTIF(Clearances!$B:$B,"Tower A") -> 0 | E10: =COUNTIFS(Clearances!$E:$E,$A10,Clearances!$B:$B,"Tower B") -> 2 | F10: =E10/COUNTIF(Clearances!$B:$B,"Tower B") -> 0.0072992701 | G10: =C10+E10 -> 2 | H10: =G10/(COUNTA(Clearances!$A:$A)-1) -> 0.0036166365
A11: F08 | B11: Family | C11: =COUNTIFS(Clearances!$E:$E,$A11,Clearances!$B:$B,"Tower A") -> 0 | D11: =C11/COUNTIF(Clearances!$B:$B,"Tower A") -> 0 | E11: =COUNTIFS(Clearances!$E:$E,$A11,Clearances!$B:$B,"Tower B") -> 2 | F11: =E11/COUNTIF(Clearances!$B:$B,"Tower B") -> 0.0072992701 | G11: =C11+E11 -> 2 | H11: =G11/(COUNTA(Clearances!$A:$A)-1) -> 0.0036166365
A12: FADA | B12: Family ADA | C12: =COUNTIFS(Clearances!$E:$E,$A12,Clearances!$B:$B,"Tower A") -> 1 | D12: =C12/COUNTIF(Clearances!$B:$B,"Tower A") -> 0.0035842294 | E12: =COUNTIFS(Clearances!$E:$E,$A12,Clearances!$B:$B,"Tower B") -> 0 | F12: =E12/COUNTIF(Clearances!$B:$B,"Tower B") -> 0 | G12: =C12+E12 -> 1 | H12: =G12/(COUNTA(Clearances!$A:$A)-1) -> 0.0018083183
A13: K01 | B13: King | C13: =COUNTIFS(Clearances!$E:$E,$A13,Clearances!$B:$B,"Tower A") -> 24 | D13: =C13/COUNTIF(Clearances!$B:$B,"Tower A") -> 0.086021505 | E13: =COUNTIFS(Clearances!$E:$E,$A13,Clearances!$B:$B,"Tower B") -> 10 | F13: =E13/COUNTIF(Clearances!$B:$B,"Tower B") -> 0.03649635 | G13: =C13+E13 -> 34 | H13: =G13/(COUNTA(Clearances!$A:$A)-1) -> 0.061482821
... A62: PS03 | B62: Premium Suite | C62: =COUNTIFS(Clearances!$E:$E,$A62,Clearances!$B:$B,"Tower A") -> 0 | D62: =C62/COUNTIF(Clearances!$B:$B,"Tower A") -> 0 | E62: =COUNTIFS(Clearances!$E:$E,$A62,Clearances!$B:$B,"Tower B") -> 6 | F62: =E62/COUNTIF(Clearances!$B:$B,"Tower B") -> 0.02189781 | G62: =C62+E62 -> 6 | H62: =G62/(COUNTA(Clearances!$A:$A)-1) -> 0.01084991
A63: TOTAL | C63: =SUM(C2:C62) -> 279 | E63: =SUM(E2:E62) -> 288 | G63: =SUM(G2:G62) -> 567

Sheet Lists
A1: Status | B1: Colour | C1: Meaning | D1: Counts as | E1: Clearance | F1: Colour
A2: A | B2: #00B050 | C2: Approved | D2: approved | E2: Provided | F2: green
A3: B | B3: #00B050 | C3: Approved as Noted | D3: approved | E3: Partially Provided | F3: amber
A4: UR | B4: #FFC000 | C4: Under Review | D4: review | E4: Pending | F4: red
A5: C | B5: #FF0000 | C5: Code C - Revise & Resubmit | D5: revise | E5: Not Requested | F5: grey
A6: TBS | B6: #BFBFBF | C6: To Be Submitted | D6: pending | E6: N/A | F6: grey
A7: Coordinated | B7: #B5E6A2 | C7: Coordination sketch provided (shown instead of a non-approved MEP/ELV status) | D7: coordinated

Sheet Config
A1: Key | B1: Value | C1: Notes
A2: Project | B2: Qiddiya Water Park Hotel (WPH) | C2: Shown in page header
A3: Base URL | B3: https://wph-bujv.github.io/wph-rooms/ | C3: Web address of the room page. QR content = Base URL + ?room=<QR ID>
A4: Data last updated | C4: Type the date you last updated this file – shown on every page
A5: Updated by | B5: Technical Department - BUJV
A6: Footer note | B6: Live status from the WPH Room QR Status Register. For information only – refer to the latest approved documents.
